Workbook

Sheet Consolidato
A1: anno | B1: mese | C1: macchina | D1: ore_produzione | E1: pezzi_prodotti | F1: consumo_kwh | G1: lettura | H1: costo_energia_per_kwh | I1: costo_macchina | J1: consumo_bolletta_kwh | K1: totale_bolletta
A2: 2024 | B2: 1 | C2: ASS1 | D2: 151.33 | E2: 127305 | H2: 0.2557 | J2: 64934 | K2: 16601.39
A3: 2024 | B3: 2 | C3: ASS1 | D3: 130.12 | E3: 117666 | H3: 0.2378 | J3: 71197 | K3: 16934
A4: 2024 | B4: 3 | C4: ASS1 | D4: 80.25 | E4: 54604 | H4: 0.2428 | J4: 51152 | K4: 12419.74
A5: 2024 | B5: 4 | C5: ASS1 | D5: 81.52 | E5: 59880 | H5: 0.2416 | J5: 45316 | K5: 10948.47
A6: 2024 | B6: 5 | C6: ASS1 | D6: 124.43 | E6: 86479 | H6: 0.2507 | J6: 51330 | K6: 12868.58
A7: 2024 | B7: 6 | C7: ASS1 | D7: 91.02 | E7: 76618 | H7: 0.2722 | J7: 42151 | K7: 11473.9
A8: 2024 | B8: 7 | C8: ASS1 | D8: 88.15 | E8: 60539 | H8: 0.287 | J8: 67581 | K8: 19396.73
A9: 2024 | B9: 8 | C9: ASS1 | D9: 30.53 | E9: 20210 | H9: 0.3047 | J9: 44796 | K9: 13651.04
A10: 2024 | B10: 9 | C10: ASS1 | D10: 69.32 | E10: 50341 | H10: 0.2904 | J10: 52599 | K10: 15277.15
A11: 2024 | B11: 10 | C11: ASS1 | D11: 93.7 | E11: 68387 | H11: 0.2856 | J11: 54362 | K11: 15523.99
A12: 2024 | B12: 11 | C12: ASS1 | D12: 130.2 | E12: 86845 | F12: 66.33 | H12: 0.307 | I12: 20.36331 | J12: 64157 | K12: 19751.41
A13: 2024 | B13: 12 | C13: ASS1 | D13: 70.15 | E13: 37100 | F13: 38.64 | H13: 0.331 | I13: 12.78984 | J13: 51593 | K13: 17063.94
A14: 2025 | B14: 1 | C14: ASS1 | D14: 182.2 | E14: 0 | F14: 55.34 | H14: 0.335 | I14: 18.5389 | J14: 61904 | K14: 20875.39
A15: 2025 | B15: 2 | C15: ASS1 | D15: 127.5 | E15: 0 | F15: 64.14 | H15: 0.334 | I15: 21.42276 | J15: 60366 | K15: 20173.7
A16: 2025 | B16: 3 | C16: ASS1 | D16: 116.1 | E16: 0 | F16: 52.57 | H16: 0.286 | I16: 15.03502 | J16: 58209 | K16: 16648.58
A17: 2025 | B17: 4 | C17: ASS1 | D17: 67.9 | E17: 0 | F17: 35.27 | H17: 0.2655 | I17: 9.364185 | J17: 41269 | K17: 10956.7
A18: 2025 | B18: 5 | C18: ASS1 | D18: 74.4 | E18: 0 | F18: 36.76 | H18: 0.2575 | I18: 9.4657 | J18: 30809 | K18: 7932.95
A19: 2025 | B19: 6 | C19: ASS1 | D19: 35 | E19: 0 | F19: 0 | H19: 0.355 | I19: 0 | J19: 33644 | K19: 11949.42
A20: 2025 | B20: 7 | C20: ASS1 | D20: 95.4 | E20: 0 | F20: 0 | H20: 0.296 | I20: 0 | J20: 51483 | K20: 15262.33
A21: 2025 | B21: 8 | C21: ASS1 | D21: 6.11 | E21: 5236 | F21: 0 | H21: 0.3268 | I21: 0 | J21: 17650 | K21: 5768.63
A22: 2025 | B22: 9 | C22: ASS1 | D22: 128.79 | E22: 96569 | F22: 1 | H22: 0 | I22: 0 | J22: 0 | K22: 0
A23: 2025 | B23: 10 | C23: ASS1 | H23: 0 | I23: 0 | J23: 0 | K23: 0
A24: 2025 | B24: 11 | C24: ASS1 | H24: 0 | I24: 0 | J24: 0 | K24: 0
A25: 2025 | B25: 12 | C25: ASS1 | H25: 0 | I25: 0 | J25: 0 | K25: 0
A26: 2024 | B26: 1 | C26: F01 | D26: 171.92 | E26: 143772 | H26: 0.2557 | J26: 64934 | K26: 16601.39
A27: 2024 | B27: 2 | C27: F01 | D27: 119.51 | E27: 99614 | H27: 0.2378 | J27: 71197 | K27: 16934
A28: 2024 | B28: 3 | C28: F01 | D28: 41.33 | E28: 30484 | H28: 0.2428 | J28: 51152 | K28: 12419.74
A29: 2024 | B29: 4 | C29: F01 | D29: 12.44 | E29: 11700 | H29: 0.2416 | J29: 45316 | K29: 10948.47
A30: 2024 | B30: 5 | C30: F01 | D30: 107.52 | E30: 106500 | H30: 0.2507 | J30: 51330 | K30: 12868.58
A31: 2024 | B31: 6 | C31: F01 | D31: 90.79 | E31: 36912 | H31: 0.2722 | J31: 42151 | K31: 11473.9
A32: 2024 | B32: 7 | C32: F01 | D32: 132.66 | E32: 20988 | H32: 0.287 | J32: 67581 | K32: 19396.73
A33: 2024 | B33: 8 | C33: F01 | D33: 33.49 | E33: 31135 | H33: 0.3047 | J33: 44796 | K33: 13651.04
A34: 2024 | B34: 9 | C34: F01 | D34: 217.54 | E34: 65920 | H34: 0.2904 | J34: 52599 | K34: 15277.15
A35: 2024 | B35: 10 | C35: F01 | D35: 96.65 | E35: 100508 | H35: 0.2856 | J35: 54362 | K35: 15523.99
A36: 2024 | B36: 11 | C36: F01 | D36: 200 | E36: 85000 | F36: 745.92 | H36: 0.307 | I36: 228.99744 | J36: 64157 | K36: 19751.41
A37: 2024 | B37: 12 | C37: F01 | D37: 59.3 | E37: 49458 | F37: 312.14 | H37: 0.331 | I37: 103.31834 | J37: 51593 | K37: 17063.94
A38: 2025 | B38: 1 | C38: F01 | D38: 129.8 | E38: 81089 | F38: 428.89 | H38: 0.335 | I38: 143.67815 | J38: 61904 | K38: 20875.39
A39: 2025 | B39: 2 | C39: F01 | D39: 153.8 | E39: 90790 | F39: 492.78 | H39: 0.334 | I39: 164.58852 | J39: 60366 | K39: 20173.7
A40: 2025 | B40: 3 | C40: F01 | D40: 94.6 | E40: 82524 | F40: 407.33 | H40: 0.286 | I40: 116.49638 | J40: 58209 | K40: 16648.58
...

Sheet ASS1
A1: anno | B1: mese | C1: macchina o impianto | D1: ore produzione macchina | E1: pezzi prodotti | F1: consumo | G1: lettura | H1: costo energia | I1: costo macchina | J1: consumo da bolletta | K1: totale bolletta
A2: 2024 | B2: 1 | C2: ASS1 | D2: 151.33 | E2: 127305 | H2: =Tabelle!F111 -> 0.2557 | J2: =Tabelle!B111 -> 64934 | K2: =Tabelle!G85 -> 16601.39
A3: 2024 | B3: 2 | C3: ASS1 | D3: 130.12 | E3: 117666 | H3: =Tabelle!F112 -> 0.2378 | J3: =Tabelle!B112 -> 71197 | K3: =Tabelle!G86 -> 16934
A4: 2024 | B4: 3 | C4: ASS1 | D4: 80.25 | E4: 54604 | H4: =Tabelle!F113 -> 0.2428 | J4: =Tabelle!B113 -> 51152 | K4: =Tabelle!G87 -> 12419.74
A5: 2024 | B5: 4 | C5: ASS1 | D5: 81.52 | E5: 59880 | H5: =Tabelle!F114 -> 0.2416 | J5: =Tabelle!B114 -> 45316 | K5: =Tabelle!G88 -> 10948.47
A6: 2024 | B6: 5 | C6: ASS1 | D6: 124.43 | E6: 86479 | H6: =Tabelle!F115 -> 0.2507 | J6: =Tabelle!B115 -> 51330 | K6: =Tabelle!G89 -> 12868.58
A7: 2024 | B7: 6 | C7: ASS1 | D7: 91.02 | E7: 76618 | H7: =Tabelle!F116 -> 0.2722 | J7: =Tabelle!B116 -> 42151 | K7: =Tabelle!G90 -> 11473.9
A8: 2024 | B8: 7 | C8: ASS1 | D8: 88.15 | E8: 60539 | H8: =Tabelle!F117 -> 0.287 | J8: =Tabelle!B117 -> 67581 | K8: =Tabelle!G91 -> 19396.73
A9: 2024 | B9: 8 | C9: ASS1 | D9: 30.53 | E9: 20210 | H9: =Tabelle!F118 -> 0.3047 | J9: =Tabelle!B118 -> 44796 | K9: =Tabelle!G92 -> 13651.04
A10: 2024 | B10: 9 | C10: ASS1 | D10: 69.32 | E10: 50341 | H10: =Tabelle!F119 -> 0.2904 | J10: =Tabelle!B119 -> 52599 | K10: =Tabelle!G93 -> 15277.15
A11: 2024 | B11: 10 | C11: ASS1 | D11: 93.7 | E11: 68387 | H11: =Tabelle!F120 -> 0.2856 | J11: =Tabelle!B120 -> 54362 | K11: =Tabelle!G94 -> 15523.99
A12: 2024 | B12: 11 | C12: ASS1 | D12: =Tabelle!Y20 -> 130.2 | E12: =Tabelle!Y36 -> 86845 | F12: 66.33 | H12: =Tabelle!F121 -> 0.307 | I12: =F12*H12 -> 20.36331 | J12: =Tabelle!B121 -> 64157 | K12: =Tabelle!G95 -> 19751.41
A13: 2024 | B13: 12 | C13: ASS1 | D13: =Tabelle!Y21 -> 70.15 | E13: =Tabelle!Y37 -> 37100 | F13: 38.64 | H13: =Tabelle!F122 -> 0.331 | I13: =F13*H13 -> 12.78984 | J13: =Tabelle!B122 -> 51593 | K13: =Tabelle!G96 -> 17063.94
A14: 2025 | B14: 1 | C14: ASS1 | D14: =Tabelle!Y22 -> 182.2 | E14: =Tabelle!Y38 -> 0 | F14: 55.34 | H14: =Tabelle!F123 -> 0.335 | I14: =F14*H14 -> 18.5389 | J14: =Tabelle!B123 -> 61904 | K14: =Tabelle!G97 -> 20875.39
A15: 2025 | B15: 2 | C15: ASS1 | D15: =Tabelle!Y23 -> 127.5 | E15: =Tabelle!Y39 -> 0 | F15: 64.14 | H15: =Tabelle!F124 -> 0.334 | I15: =F15*H15 -> 21.42276 | J15: =Tabelle!B124 -> 60366 | K15: =Tabelle!G98 -> 20173.7
A16: 2025 | B16: 3 | C16: ASS1 | D16: =Tabelle!Y24 -> 116.1 | E16: =Tabelle!Y40 -> 0 | F16: 52.57 | H16: =Tabelle!F125 -> 0.286 | I16: =F16*H16 -> 15.03502 | J16: =Tabelle!B125 -> 58209 | K16: =Tabelle!G99 -> 16648.58
A17: 2025 | B17: 4 | C17: ASS1 | D17: =Tabelle!Y25 -> 67.9 | E17: =Tabelle!Y41 -> 0 | F17: 35.27 | H17: =Tabelle!F126 -> 0.2655 | I17: =F17*H17 -> 9.364185 | J17: =Tabelle!B126 -> 41269 | K17: =Tabelle!G100 -> 10956.7
A18: 2025 | B18: 5 | C18: ASS1 | D18: =Tabelle!Y26 -> 74.4 | E18: =Tabelle!Y42 -> 0 | F18: 36.76 | H18: =Tabelle!F127 -> 0.2575 | I18: =F18*H18 -> 9.4657 | J18: =Tabelle!B127 -> 30809 | K18: =Tabelle!G101 -> 7932.95
A19: 2025 | B19: 6 | C19: ASS1 | D19: =Tabelle!Y27 -> 35 | E19: =Tabelle!Y43 -> 0 | F19: 0 | H19: =Tabelle!F128 -> 0.355 | I19: =F19*H19 -> 0 | J19: =Tabelle!B128 -> 33644 | K19: =Tabelle!G102 -> 11949.42
A20: 2025 | B20: 7 | C20: ASS1 | D20: =Tabelle!Y28 -> 95.4 | E20: =Tabelle!Y44 -> 0 | F20: 0 | H20: =Tabelle!F129 -> 0.296 | I20: =F20*H20 -> 0 | J20: =Tabelle!B129 -> 51483 | K20: =Tabelle!G103 -> 15262.33
A21: 2025 | B21: 8 | C21: ASS1 | D21: =Tabelle!Y29 -> 6.11 | E21: =Tabelle!Y45 -> 5236 | F21: 0 | H21: =Tabelle!F130 -> 0.3268 | I21: =F21*H21 -> 0 | J21: =Tabelle!B130 -> 17650 | K21: =Tabelle!G104 -> 5768.63
A22: 2025 | B22: 9 | C22: ASS1 | D22: =Tabelle!Y30 -> 128.79 | E22: =Tabelle!Y46 -> 96569 | F22: 1 | H22: =Tabelle!F131 -> 0.2732 | I22: =F22*H22 -> 0.2732 | J22: =Tabelle!B131 -> 47214 | K22: =Tabelle!G105 -> 12897.86
A23: 2025 | B23: 10 | C23: ASS1 | D23: =Tabelle!Y31 -> 0 | E23: =Tabelle!Y47 -> 6740 | F23: 2 | H23: =Tabelle!F132 -> 0.2134 | I23: =F23*H23 -> 0.4268 | J23: =Tabelle!B132 -> 47533 | K23: =Tabelle!G106 -> 13101.09
A24: 2025 | B24: 11 | C24: ASS1 | H24: =Tabelle!F133 -> 0.2261 | I24: =F24*H24 -> 0 | J24: =Tabelle!B133 -> 50662 | K24: =Tabelle!G111 -> 0
A25: 2025 | B25: 12 | C25: ASS1 | H25: =Tabelle!F134 -> 0 | I25: =F25*H25 -> 0 | J25: =Tabelle!B134 -> 0 | K25: =Tabelle!G112 -> 0
A26: 2026 | B26: 7 | C26: ASS1 | H26: =Tabelle!F135 -> 0 | I26: =F26*H26 -> 0 | J26: =Tabelle!B135 -> 0 | K26: =Tabelle!G113 -> 0

Sheet F01
A1: anno | B1: mese | C1: macchina o impianto | D1: ore produzione macchina | E1: pezzi prodotti | F1: consumo | G1: lettura | H1: costo energia | I1: costo macchina | J1: consumo da bolletta | K1: totale bolletta
A2: 2024 | B2: 1 | C2: F01 | D2: 171.92 | E2: 143772 | H2: =Tabelle!F111 -> 0.2557 | J2: =Tabelle!B111 -> 64934 | K2: =Tabelle!G85 -> 16601.39
A3: 2024 | B3: 2 | C3: F01 | D3: 119.51 | E3: 99614 | H3: =Tabelle!F112 -> 0.2378 | J3: =Tabelle!B112 -> 71197 | K3: =Tabelle!G86 -> 16934
A4: 2024 | B4: 3 | C4: F01 | D4: 41.33 | E4: 30484 | H4: =Tabelle!F113 -> 0.2428 | J4: =Tabelle!B113 -> 51152 | K4: =Tabelle!G87 -> 12419.74
A5: 2024 | B5: 4 | C5: F01 | D5: 12.44 | E5: 11700 | H5: =Tabelle!F114 -> 0.2416 | J5: =Tabelle!B114 -> 45316 | K5: =Tabelle!G88 -> 10948.47
A6: 2024 | B6: 5 | C6: F01 | D6: 107.52 | E6: 106500 | H6: =Tabelle!F115 -> 0.2507 | J6: =Tabelle!B115 -> 51330 | K6: =Tabelle!G89 -> 12868.58
A7: 2024 | B7: 6 | C7: F01 | D7: 90.79 | E7: 36912 | H7: =Tabelle!F116 -> 0.2722 | J7: =Tabelle!B116 -> 42151 | K7: =Tabelle!G90 -> 11473.9
A8: 2024 | B8: 7 | C8: F01 | D8: 132.66 | E8: 20988 | H8: =Tabelle!F117 -> 0.287 | J8: =Tabelle!B117 -> 67581 | K8: =Tabelle!G91 -> 19396.73
A9: 2024 | B9: 8 | C9: F01 | D9: 33.49 | E9: 31135 | H9: =Tabelle!F118 -> 0.3047 | J9: =Tabelle!B118 -> 44796 | K9: =Tabelle!G92 -> 13651.04
A10: 2024 | B10: 9 | C10: F01 | D10: 217.54 | E10: 65920 | H10: =Tabelle!F119 -> 0.2904 | J10: =Tabelle!B119 -> 52599 | K10: =Tabelle!G93 -> 15277.15
A11: 2024 | B11: 10 | C11: F01 | D11: 96.65 | E11: 100508 | H11: =Tabelle!F120 -> 0.2856 | J11: =Tabelle!B120 -> 54362 | K11: =Tabelle!G94 -> 15523.99
A12: 2024 | B12: 11 | C12: F01 | D12: =Tabelle!B20 -> 200 | E12: =Tabelle!B36 -> 85000 | F12: =Tabelle!B4 -> 745.92 | H12: =Tabelle!F121 -> 0.307 | I12: =F12*H12 -> 228.99744 | J12: =Tabelle!B121 -> 64157 | K12: =Tabelle!G95 -> 19751.41
A13: 2024 | B13: 12 | C13: F01 | D13: =Tabelle!B21 -> 59.3 | E13: =Tabelle!B37 -> 49458 | F13: =Tabelle!B5 -> 312.14 | H13: =Tabelle!F122 -> 0.331 | I13: =F13*H13 -> 103.31834 | J13: =Tabelle!B122 -> 51593 | K13: =Tabelle!G96 -> 17063.94
A14: 2025 | B14: 1 | C14: F01 | D14: =Tabelle!B22 -> 129.8 | E14: =Tabelle!B38 -> 81089 | F14: =Tabelle!B6 -> 428.89 | H14: =Tabelle!F123 -> 0.335 | I14: =F14*H14 -> 143.67815 | J14: =Tabelle!B123 -> 61904 | K14: =Tabelle!G97 -> 20875.39
A15: 2025 | B15: 2 | C15: F01 | D15: =Tabelle!B23 -> 153.8 | E15: =Tabelle!B39 -> 90790 | F15: =Tabelle!B7 -> 492.78 | H15: =Tabelle!F124 -> 0.334 | I15: =F15*H15 -> 164.58852 | J15: =Tabelle!B124 -> 60366 | K15: =Tabelle!G98 -> 20173.7
A16: 2025 | B16: 3 | C16: F01 | D16: =Tabelle!B24 -> 94.6 | E16: =Tabelle!B40 -> 82524 | F16: =Tabelle!B8 -> 407.33 | H16: =Tabelle!F125 -> 0.286 | I16: =F16*H16 -> 116.49638 | J16: =Tabelle!B125 -> 58209 | K16: =Tabelle!G99 -> 16648.58
A17: 2025 | B17: 4 | C17: F01 | D17: =Tabelle!B25 -> 84.6 | E17: =Tabelle!B41 -> 89516 | F17: =Tabelle!B9 -> 339.18 | H17: =Tabelle!F126 -> 0.2655 | I17: =F17*H17 -> 90.05229 | J17: =Tabelle!B126 -> 41269 | K17: =Tabelle!G100 -> 10956.7
A18: 2025 | B18: 5 | C18: F01 | D18: =Tabelle!B26 -> 135.2 | E18: =Tabelle!B42 -> 36500 | F18: =Tabelle!B10 -> 253.47 | H18: =Tabelle!F127 -> 0.2575 | I18: =F18*H18 -> 65.268525 | J18: =Tabelle!B127 -> 30809 | K18: =Tabelle!G101 -> 7932.95
A19: 2025 | B19: 6 | C19: F01 | D19: =Tabelle!B27 -> 18.2 | E19: =Tabelle!B43 -> 20900 | F19: =Tabelle!B11 -> 97.44 | H19: =Tabelle!F128 -> 0.355 | I19: =F19*H19 -> 34.5912 | J19: =Tabelle!B128 -> 33644 | K19: =Tabelle!G102 -> 11949.42
A20: 2025 | B20: 7 | C20: F01 | D20: =Tabelle!B28 -> 173.2 | E20: =Tabelle!B44 -> 197200 | F20: =Tabelle!B12 -> 448.6 | H20: =Tabelle!F129 -> 0.296 | I20: =F20*H20 -> 132.7856 | J20: =Tabelle!B129 -> 51483 | K20: =Tabelle!G103 -> 15262.33
A21: 2025 | B21: 8 | C21: F01 | D21: =Tabelle!B29 -> 0 | E21: =Tabelle!B45 -> 0 | F21: =Tabelle!B13 -> 4.05 | H21: =Tabelle!F130 -> 0.3268 | I21: =F21*H21 -> 1.32354 | J21: =Tabelle!B130 -> 17650 | K21: =Tabelle!G104 -> 5768.63
A22: 2025 | B22: 9 | C22: F01 | D22: =Tabelle!B30 -> 40.05 | E22: =Tabelle!B46 -> 16300 | F22: =Tabelle!B14 -> 179.22 | H22: =Tabelle!F131 -> 0.2732 | I22: =F22*H22 -> 48.962904 | J22: =Tabelle!B131 -> 47214 | K22: =Tabelle!G105 -> 12897.86
A23: 2025 | B23: 10 | C23: F01 | D23: =Tabelle!B31 -> 40.92 | E23: =Tabelle!B47 -> 20349 | F23: =Tabelle!B15 -> 477.62 | H23: =Tabelle!F132 -> 0.2134 | I23: =F23*H23 -> 101.92411 | J23: =Tabelle!B132 -> 47533 | K23: =Tabelle!G106 -> 13101.09
... A38: 2038 | B38: 13 | C38: F13 | D38: =Tabelle!B46 -> 16300 | E38: =Tabelle!B62 -> 2887.25 | F38: =Tabelle!B30 -> 40.05 | H38: =Tabelle!F147 -> 0 | I38: =F38*H38 -> 0 | J38: =Tabelle!B147 -> 0 | K38: =Tabelle!G121 -> 0

Sheet F02
A1: anno | B1: mese | C1: macchina o impianto | D1: ore produzione macchina | E1: pezzi prodotti | F1: consumo | G1: lettura | H1: costo energia | I1: costo macchina | J1: consumo da bolletta | K1: totale bolletta
A2: 2024 | B2: 1 | C2: F02 | D2: 141.59 | E2: 74096 | H2: =Tabelle!F111 -> 0.2557 | J2: =Tabelle!B111 -> 64934 | K2: =Tabelle!G85 -> 16601.39
A3: 2024 | B3: 2 | C3: F02 | D3: 211.19 | E3: 76550 | H3: =Tabelle!F112 -> 0.2378 | J3: =Tabelle!B112 -> 71197 | K3: =Tabelle!G86 -> 16934
A4: 2024 | B4: 3 | C4: F02 | D4: 83.45 | E4: 47000 | H4: =Tabelle!F113 -> 0.2428 | J4: =Tabelle!B113 -> 51152 | K4: =Tabelle!G87 -> 12419.74
A5: 2024 | B5: 4 | C5: F02 | D5: 0 | E5: 10860 | H5: =Tabelle!F114 -> 0.2416 | J5: =Tabelle!B114 -> 45316 | K5: =Tabelle!G88 -> 10948.47
A6: 2024 | B6: 5 | C6: F02 | D6: 69.22 | E6: 13432 | H6: =Tabelle!F115 -> 0.2507 | J6: =Tabelle!B115 -> 51330 | K6: =Tabelle!G89 -> 12868.58
A7: 2024 | B7: 6 | C7: F02 | D7: 62.19 | E7: 36744 | H7: =Tabelle!F116 -> 0.2722 | J7: =Tabelle!B116 -> 42151 | K7: =Tabelle!G90 -> 11473.9
A8: 2024 | B8: 7 | C8: F02 | D8: 59.82 | E8: 18500 | H8: =Tabelle!F117 -> 0.287 | J8: =Tabelle!B117 -> 67581 | K8: =Tabelle!G91 -> 19396.73
A9: 2024 | B9: 8 | C9: F02 | D9: 45.05 | E9: 17088 | H9: =Tabelle!F118 -> 0.3047 | J9: =Tabelle!B118 -> 44796 | K9: =Tabelle!G92 -> 13651.04
A10: 2024 | B10: 9 | C10: F02 | D10: 84.73 | E10: 13260 | H10: =Tabelle!F119 -> 0.2904 | J10: =Tabelle!B119 -> 52599 | K10: =Tabelle!G93 -> 15277.15
A11: 2024 | B11: 10 | C11: F02 | D11: 45.11 | E11: 4700 | H11: =Tabelle!F120 -> 0.2856 | J11: =Tabelle!B120 -> 54362 | K11: =Tabelle!G94 -> 15523.99
A12: 2024 | B12: 11 | C12: F02 | D12: =Tabelle!C20 -> 103.3 | E12: =Tabelle!C36 -> 15405 | F12: =Tabelle!C4 -> 511.15 | H12: =Tabelle!F121 -> 0.307 | I12: =F12*H12 -> 156.92305 | J12: =Tabelle!B121 -> 64157 | K12: =Tabelle!G95 -> 19751.41
A13: 2024 | B13: 12 | C13: F02 | D13: =Tabelle!C21 -> 89.7 | E13: =Tabelle!C37 -> 100138 | F13: =Tabelle!C5 -> 357.13 | H13: =Tabelle!F122 -> 0.331 | I13: =F13*H13 -> 118.21003 | J13: =Tabelle!B122 -> 51593 | K13: =Tabelle!G96 -> 17063.94
A14: 2025 | B14: 1 | C14: F02 | D14: =Tabelle!C22 -> 99.7 | E14: =Tabelle!C38 -> 6278 | F14: =Tabelle!C6 -> 502.77 | H14: =Tabelle!F123 -> 0.335 | I14: =F14*H14 -> 168.42795 | J14: =Tabelle!B123 -> 61904 | K14: =Tabelle!G97 -> 20875.39
A15: 2025 | B15: 2 | C15: F02 | D15: =Tabelle!C23 -> 77.6 | E15: =Tabelle!C39 -> 41985 | F15: =Tabelle!C7 -> 286.44 | H15: =Tabelle!F124 -> 0.334 | I15: =F15*H15 -> 95.67096 | J15: =Tabelle!B124 -> 60366 | K15: =Tabelle!G98 -> 20173.7
A16: 2025 | B16: 3 | C16: F02 | D16: =Tabelle!C24 -> 53.7 | E16: =Tabelle!C40 -> 36925 | F16: =Tabelle!C8 -> 402.32 | H16: =Tabelle!F125 -> 0.286 | I16: =F16*H16 -> 115.06352 | J16: =Tabelle!B125 -> 58209 | K16: =Tabelle!G99 -> 16648.58
A17: 2025 | B17: 4 | C17: F02 | D17: =Tabelle!C25 -> 108.4 | E17: =Tabelle!C41 -> 19510 | F17: =Tabelle!C9 -> 398.69 | H17: =Tabelle!F126 -> 0.2655 | I17: =F17*H17 -> 105.85219 | J17: =Tabelle!B126 -> 41269 | K17: =Tabelle!G100 -> 10956.7
A18: 2025 | B18: 5 | C18: F02 | D18: =Tabelle!C26 -> 2.2 | E18: =Tabelle!C42 -> 500 | F18: =Tabelle!C10 -> 66.4 | H18: =Tabelle!F127 -> 0.2575 | I18: =F18*H18 -> 17.098 | J18: =Tabelle!B127 -> 30809 | K18: =Tabelle!G101 -> 7932.95
A19: 2025 | B19: 6 | C19: F02 | D19: =Tabelle!C27 -> 15.8 | E19: =Tabelle!C43 -> 4484 | F19: =Tabelle!C11 -> 146.03 | H19: =Tabelle!F128 -> 0.355 | I19: =F19*H19 -> 51.84065 | J19: =Tabelle!B128 -> 33644 | K19: =Tabelle!G102 -> 11949.42
A20: 2025 | B20: 7 | C20: F02 | D20: =Tabelle!C28 -> 115.1 | E20: =Tabelle!C44 -> 51000 | F20: =Tabelle!C12 -> 538.77 | H20: =Tabelle!F129 -> 0.296 | I20: =F20*H20 -> 159.47592 | J20: =Tabelle!B129 -> 51483 | K20: =Tabelle!G103 -> 15262.33
A21: 2025 | B21: 8 | C21: F02 | D21: =Tabelle!C29 -> 59.62 | E21: =Tabelle!C45 -> 35441 | F21: =Tabelle!C13 -> 163.2 | H21: =Tabelle!F130 -> 0.3268 | I21: =F21*H21 -> 53.33376 | J21: =Tabelle!B130 -> 17650 | K21: =Tabelle!G104 -> 5768.63
A22: 2025 | B22: 9 | C22: F02 | D22: =Tabelle!C30 -> 287.77 | E22: =Tabelle!C46 -> 112280 | F22: =Tabelle!C14 -> 746.4 | H22: =Tabelle!F131 -> 0.2732 | I22: =F22*H22 -> 203.91648 | J22: =Tabelle!B131 -> 47214 | K22: =Tabelle!G105 -> 12897.86
A23: 2025 | B23: 10 | C23: F02 | D23: =Tabelle!C31 -> 72.31 | E23: =Tabelle!C47 -> 28690 | F23: =Tabelle!C15 -> 800.61 | H23: =Tabelle!F132 -> 0.2134 | I23: =F23*H23 -> 170.85017 | J23: =Tabelle!B132 -> 47533 | K23: =Tabelle!G106 -> 13101.09
A24: 2025 | B24: 11 | C24: F02 | H24: =Tabelle!F133 -> 0.2261 | J24: =Tabelle!B133 -> 50662 | K24: =Tabelle!G111 -> 0
A25: 2025 | B25: 12 | C25: F02 | H25: =Tabelle!F134 -> 0 | J25: =Tabelle!B134 -> 0 | K25: =Tabelle!G112 -> 0

Sheet F03
A1: anno | B1: mese | C1: macchina o impianto | D1: ore produzione macchina | E1: pezzi prodotti | F1: consumo | G1: lettura | H1: costo energia | I1: costo macchina | J1: consumo da bolletta | K1: totale bolletta
A2: 2024 | B2: 1 | C2: F03 | D2: 181.16 | E2: 157102 | H2: =Tabelle!F111 -> 0.2557 | J2: =Tabelle!B111 -> 64934 | K2: =Tabelle!G85 -> 16601.39
A3: 2024 | B3: 2 | C3: F03 | D3: 228.07 | E3: 144108 | H3: =Tabelle!F112 -> 0.2378 | J3: =Tabelle!B112 -> 71197 | K3: =Tabelle!G86 -> 16934
A4: 2024 | B4: 3 | C4: F03 | D4: 14.89 | E4: 11200 | H4: =Tabelle!F113 -> 0.2428 | J4: =Tabelle!B113 -> 51152 | K4: =Tabelle!G87 -> 12419.74
A5: 2024 | B5: 4 | C5: F03 | D5: 12.3 | E5: 4860 | H5: =Tabelle!F114 -> 0.2416 | J5: =Tabelle!B114 -> 45316 | K5: =Tabelle!G88 -> 10948.47
A6: 2024 | B6: 5 | C6: F03 | D6: 133.93 | E6: 75309 | H6: =Tabelle!F115 -> 0.2507 | J6: =Tabelle!B115 -> 51330 | K6: =Tabelle!G89 -> 12868.58
A7: 2024 | B7: 6 | C7: F03 | D7: 9.27 | E7: 3083 | H7: =Tabelle!F116 -> 0.2722 | J7: =Tabelle!B116 -> 42151 | K7: =Tabelle!G90 -> 11473.9
A8: 2024 | B8: 7 | C8: F03 | D8: 93.51 | E8: 68064 | H8: =Tabelle!F117 -> 0.287 | J8: =Tabelle!B117 -> 67581 | K8: =Tabelle!G91 -> 19396.73
A9: 2024 | B9: 8 | C9: F03 | D9: 130.57 | E9: 106836 | H9: =Tabelle!F118 -> 0.3047 | J9: =Tabelle!B118 -> 44796 | K9: =Tabelle!G92 -> 13651.04
A10: 2024 | B10: 9 | C10: F03 | D10: 51.16 | E10: 37600 | H10: =Tabelle!F119 -> 0.2904 | J10: =Tabelle!B119 -> 52599 | K10: =Tabelle!G93 -> 15277.15
A11: 2024 | B11: 10 | C11: F03 | D11: 66.32 | E11: 48808 | H11: =Tabelle!F120 -> 0.2856 | J11: =Tabelle!B120 -> 54362 | K11: =Tabelle!G94 -> 15523.99
A12: 2024 | B12: 11 | C12: F03 | D12: =Tabelle!D20 -> 100.6 | E12: =Tabelle!D36 -> 71217 | F12: =Tabelle!D4 -> 931.35 | H12: =Tabelle!F121 -> 0.307 | I12: =F12*H12 -> 285.92445 | J12: =Tabelle!B121 -> 64157 | K12: =Tabelle!G95 -> 19751.41
A13: 2024 | B13: 12 | C13: F03 | D13: =Tabelle!D21 -> 18.7 | E13: =Tabelle!D37 -> 7167 | F13: =Tabelle!D5 -> 138.46 | H13: =Tabelle!F122 -> 0.331 | I13: =F13*H13 -> 45.83026 | J13: =Tabelle!B122 -> 51593 | K13: =Tabelle!G96 -> 17063.94
A14: 2025 | B14: 1 | C14: F03 | D14: =Tabelle!D22 -> 112.5 | E14: =Tabelle!D38 -> 32200 | F14: =Tabelle!D6 -> 562.68 | H14: =Tabelle!F123 -> 0.335 | I14: =F14*H14 -> 188.4978 | J14: =Tabelle!B123 -> 61904 | K14: =Tabelle!G97 -> 20875.39
A15: 2025 | B15: 2 | C15: F03 | D15: =Tabelle!D23 -> 137.8 | E15: =Tabelle!D39 -> 57200 | F15: =Tabelle!D7 -> 838.13 | H15: =Tabelle!F124 -> 0.334 | I15: =F15*H15 -> 279.93542 | J15: =Tabelle!B124 -> 60366 | K15: =Tabelle!G98 -> 20173.7
A16: 2025 | B16: 3 | C16: F03 | D16: =Tabelle!D24 -> 80.1 | E16: =Tabelle!D40 -> 46789 | F16: =Tabelle!D8 -> 740.02 | H16: =Tabelle!F125 -> 0.286 | I16: =F16*H16 -> 211.64572 | J16: =Tabelle!B125 -> 58209 | K16: =Tabelle!G99 -> 16648.58
A17: 2025 | B17: 4 | C17: F03 | D17: =Tabelle!D25 -> 167.4 | E17: =Tabelle!D41 -> 36400 | F17: =Tabelle!D9 -> 742.47 | H17: =Tabelle!F126 -> 0.2655 | I17: =F17*H17 -> 197.12579 | J17: =Tabelle!B126 -> 41269 | K17: =Tabelle!G100 -> 10956.7
A18: 2025 | B18: 5 | C18: F03 | D18: =Tabelle!D26 -> 4.4 | E18: =Tabelle!D42 -> 1303 | F18: =Tabelle!D10 -> 78.85 | H18: =Tabelle!F127 -> 0.2575 | I18: =F18*H18 -> 20.303875 | J18: =Tabelle!B127 -> 30809 | K18: =Tabelle!G101 -> 7932.95
A19: 2025 | B19: 6 | C19: F03 | D19: =Tabelle!D27 -> 21.1 | E19: =Tabelle!D43 -> 12400 | F19: =Tabelle!D11 -> 99.57 | H19: =Tabelle!F128 -> 0.355 | I19: =F19*H19 -> 35.34735 | J19: =Tabelle!B128 -> 33644 | K19: =Tabelle!G102 -> 11949.42
A20: 2025 | B20: 7 | C20: F03 | D20: =Tabelle!D28 -> 113 | E20: =Tabelle!D44 -> 79954 | F20: =Tabelle!D12 -> 622.53 | H20: =Tabelle!F129 -> 0.296 | I20: =F20*H20 -> 184.26888 | J20: =Tabelle!B129 -> 51483 | K20: =Tabelle!G103 -> 15262.33
A21: 2025 | B21: 8 | C21: F03 | D21: =Tabelle!D29 -> 0 | E21: =Tabelle!D45 -> 0 | F21: =Tabelle!D13 -> 24.93 | H21: =Tabelle!F130 -> 0.3268 | I21: =F21*H21 -> 8.147124 | J21: =Tabelle!B130 -> 17650 | K21: =Tabelle!G104 -> 5768.63
A22: 2025 | B22: 9 | C22: F03 | D22: =Tabelle!D30 -> 115.01 | E22: =Tabelle!D46 -> 88600 | F22: =Tabelle!D14 -> 786.97 | H22: =Tabelle!F131 -> 0.2732 | I22: =F22*H22 -> 215.0002 | J22: =Tabelle!B131 -> 47214 | K22: =Tabelle!G105 -> 12897.86
A23: 2025 | B23: 10 | C23: F03 | D23: =Tabelle!D31 -> 4.04 | E23: =Tabelle!D47 -> 2000 | F23: =Tabelle!D15 -> 401.65 | H23: =Tabelle!F132 -> 0.2134 | I23: =F23*H23 -> 85.71211 | J23: =Tabelle!B132 -> 47533 | K23: =Tabelle!G106 -> 13101.09
A24: 2025 | B24: 11 | C24: F03 | H24: =Tabelle!F133 -> 0.2261 | J24: =Tabelle!B133 -> 50662 | K24: =Tabelle!G111 -> 0
A25: 2025 | B25: 12 | C25: F03 | H25: =Tabelle!F134 -> 0 | J25: =Tabelle!B134 -> 0 | K25: =Tabelle!G112 -> 0

Sheet F04
A1: anno | B1: mese | C1: macchina o impianto | D1: ore produzione macchina | E1: pezzi prodotti | F1: consumo | G1: lettura | H1: costo energia | I1: costo macchina | J1: consumo da bolletta | K1: totale bolletta
A2: 2024 | B2: 1 | C2: F04 | D2: 127.93 | E2: 172860 | H2: =Tabelle!F111 -> 0.2557 | J2: =Tabelle!B111 -> 64934 | K2: =Tabelle!G85 -> 16601.39
A3: 2024 | B3: 2 | C3: F04 | D3: 102.95 | E3: 61844 | H3: =Tabelle!F112 -> 0.2378 | J3: =Tabelle!B112 -> 71197 | K3: =Tabelle!G86 -> 16934
A4: 2024 | B4: 3 | C4: F04 | D4: 7.27 | E4: 6400 | H4: =Tabelle!F113 -> 0.2428 | J4: =Tabelle!B113 -> 51152 | K4: =Tabelle!G87 -> 12419.74
A5: 2024 | B5: 4 | C5: F04 | D5: 48.6 | E5: 81568 | H5: =Tabelle!F114 -> 0.2416 | J5: =Tabelle!B114 -> 45316 | K5: =Tabelle!G88 -> 10948.47
A6: 2024 | B6: 5 | C6: F04 | D6: 20.81 | E6: 11408 | H6: =Tabelle!F115 -> 0.2507 | J6: =Tabelle!B115 -> 51330 | K6: =Tabelle!G89 -> 12868.58
A7: 2024 | B7: 6 | C7: F04 | D7: 63.95 | E7: 28352 | H7: =Tabelle!F116 -> 0.2722 | J7: =Tabelle!B116 -> 42151 | K7: =Tabelle!G90 -> 11473.9
A8: 2024 | B8: 7 | C8: F04 | D8: 87.18 | E8: 60676 | H8: =Tabelle!F117 -> 0.287 | J8: =Tabelle!B117 -> 67581 | K8: =Tabelle!G91 -> 19396.73
A9: 2024 | B9: 8 | C9: F04 | D9: 64.86 | E9: 20800 | H9: =Tabelle!F118 -> 0.3047 | J9: =Tabelle!B118 -> 44796 | K9: =Tabelle!G92 -> 13651.04
A10: 2024 | B10: 9 | C10: F04 | D10: 49.66 | E10: 19730 | H10: =Tabelle!F119 -> 0.2904 | J10: =Tabelle!B119 -> 52599 | K10: =Tabelle!G93 -> 15277.15
A11: 2024 | B11: 10 | C11: F04 | D11: 162.34 | E11: 151024 | H11: =Tabelle!F120 -> 0.2856 | J11: =Tabelle!B120 -> 54362 | K11: =Tabelle!G94 -> 15523.99
A12: 2024 | B12: 11 | C12: F04 | D12: =Tabelle!E20 -> 9.6 | E12: =Tabelle!E36 -> 6000 | F12: =Tabelle!E4 -> 243.97 | H12: =Tabelle!F121 -> 0.307 | I12: =F12*H12 -> 74.89879 | J12: =Tabelle!B121 -> 64157 | K12: =Tabelle!G95 -> 19751.41
A13: 2024 | B13: 12 | C13: F04 | D13: =Tabelle!E21 -> 99.3 | E13: =Tabelle!E37 -> 50921 | F13: =Tabelle!E5 -> 836.27 | H13: =Tabelle!F122 -> 0.331 | I13: =F13*H13 -> 276.80537 | J13: =Tabelle!B122 -> 51593 | K13: =Tabelle!G96 -> 17063.94
A14: 2025 | B14: 1 | C14: F04 | D14: =Tabelle!E22 -> 112.9 | E14: =Tabelle!E38 -> 99119 | F14: =Tabelle!E6 -> 1220.5 | H14: =Tabelle!F123 -> 0.335 | I14: =F14*H14 -> 408.8675 | J14: =Tabelle!B123 -> 61904 | K14: =Tabelle!G97 -> 20875.39
A15: 2025 | B15: 2 | C15: F04 | D15: =Tabelle!E23 -> 129 | E15: =Tabelle!E39 -> 90878 | F15: =Tabelle!E7 -> 838.96 | H15: =Tabelle!F124 -> 0.334 | I15: =F15*H15 -> 280.21264 | J15: =Tabelle!B124 -> 60366 | K15: =Tabelle!G98 -> 20173.7
A16: 2025 | B16: 3 | C16: F04 | D16: =Tabelle!E24 -> 193.5 | E16: =Tabelle!E40 -> 182385 | F16: =Tabelle!E8 -> 1330.61 | H16: =Tabelle!F125 -> 0.286 | I16: =F16*H16 -> 380.55446 | J16: =Tabelle!B125 -> 58209 | K16: =Tabelle!G99 -> 16648.58
A17: 2025 | B17: 4 | C17: F04 | D17: =Tabelle!E25 -> 27.1 | E17: =Tabelle!E41 -> 22558 | F17: =Tabelle!E9 -> 566.89 | H17: =Tabelle!F126 -> 0.2655 | I17: =F17*H17 -> 150.5093 | J17: =Tabelle!B126 -> 41269 | K17: =Tabelle!G100 -> 10956.7
A18: 2025 | B18: 5 | C18: F04 | D18: =Tabelle!E26 -> 22.7 | E18: =Tabelle!E42 -> 13000 | F18: =Tabelle!E10 -> 460.46 | H18: =Tabelle!F127 -> 0.2575 | I18: =F18*H18 -> 118.56845 | J18: =Tabelle!B127 -> 30809 | K18: =Tabelle!G101 -> 7932.95
A19: 2025 | B19: 6 | C19: F04 | D19: =Tabelle!E27 -> 66.8 | E19: =Tabelle!E43 -> 36424 | F19: =Tabelle!E11 -> 1011.51 | H19: =Tabelle!F128 -> 0.355 | I19: =F19*H19 -> 359.08605 | J19: =Tabelle!B128 -> 33644 | K19: =Tabelle!G102 -> 11949.42
A20: 2025 | B20: 7 | C20: F04 | D20: =Tabelle!E28 -> 201.7 | E20: =Tabelle!E44 -> 124631 | F20: =Tabelle!E12 -> 1784 | H20: =Tabelle!F129 -> 0.296 | I20: =F20*H20 -> 528.064 | J20: =Tabelle!B129 -> 51483 | K20: =Tabelle!G103 -> 15262.33
A21: 2025 | B21: 8 | C21: F04 | D21: =Tabelle!E29 -> 18.37 | E21: =Tabelle!E45 -> 9065 | F21: =Tabelle!E13 -> 363.29 | H21: =Tabelle!F130 -> 0.3268 | I21: =F21*H21 -> 118.72317 | J21: =Tabelle!B130 -> 17650 | K21: =Tabelle!G104 -> 5768.63
A22: 2025 | B22: 9 | C22: F04 | D22: =Tabelle!E30 -> 53.02 | E22: =Tabelle!E46 -> 44000 | F22: =Tabelle!E14 -> 752.92 | H22: =Tabelle!F131 -> 0.2732 | I22: =F22*H22 -> 205.69774 | J22: =Tabelle!B131 -> 47214 | K22: =Tabelle!G105 -> 12897.86
A23: 2025 | B23: 10 | C23: F04 | D23: =Tabelle!E31 -> 19.01 | E23: =Tabelle!E47 -> 9876 | F23: =Tabelle!E15 -> 935.37 | H23: =Tabelle!F132 -> 0.2134 | I23: =F23*H23 -> 199.60796 | J23: =Tabelle!B132 -> 47533 | K23: =Tabelle!G106 -> 13101.09
A24: 2025 | B24: 11 | C24: F04 | H24: =Tabelle!F133 -> 0.2261 | I24: =F24*H24 -> 0 | J24: =Tabelle!B133 -> 50662 | K24: =Tabelle!G111 -> 0
A25: 2025 | B25: 12 | C25: F04 | H25: =Tabelle!F134 -> 0 | I25: =F25*H25 -> 0 | J25: =Tabelle!B134 -> 0 | K25: =Tabelle!G112 -> 0

Sheet F05
A1: anno | B1: mese | C1: macchina o impianto | D1: ore produzione macchina | E1: pezzi prodotti | F1: consumo | G1: lettura | H1: costo energia | I1: costo macchina | J1: consumo da bolletta | K1: totale bolletta
A2: 2024 | B2: 1 | C2: F05 | D2: 53.21 | E2: 71235 | H2: =Tabelle!F111 -> 0.2557 | J2: =Tabelle!B111 -> 64934 | K2: =Tabelle!G85 -> 16601.39
A3: 2024 | B3: 2 | C3: F05 | D3: 7.77 | E3: 11620 | H3: =Tabelle!F112 -> 0.2378 | J3: =Tabelle!B112 -> 71197 | K3: =Tabelle!G86 -> 16934
A4: 2024 | B4: 3 | C4: F05 | D4: 101.11 | E4: 77660 | H4: =Tabelle!F113 -> 0.2428 | J4: =Tabelle!B113 -> 51152 | K4: =Tabelle!G87 -> 12419.74
A5: 2024 | B5: 4 | C5: F05 | D5: 40.97 | E5: 60016 | H5: =Tabelle!F114 -> 0.2416 | J5: =Tabelle!B114 -> 45316 | K5: =Tabelle!G88 -> 10948.47
A6: 2024 | B6: 5 | C6: F05 | D6: 176.24 | E6: 58884 | H6: =Tabelle!F115 -> 0.2507 | J6: =Tabelle!B115 -> 51330 | K6: =Tabelle!G89 -> 12868.58
A7: 2024 | B7: 6 | C7: F05 | D7: 43.78 | E7: 33600 | H7: =Tabelle!F116 -> 0.2722 | J7: =Tabelle!B116 -> 42151 | K7: =Tabelle!G90 -> 11473.9
A8: 2024 | B8: 7 | C8: F05 | D8: 102.16 | E8: 81250 | H8: =Tabelle!F117 -> 0.287 | J8: =Tabelle!B117 -> 67581 | K8: =Tabelle!G91 -> 19396.73
A9: 2024 | B9: 8 | C9: F05 | D9: 16.37 | E9: 13900 | H9: =Tabelle!F118 -> 0.3047 | J9: =Tabelle!B118 -> 44796 | K9: =Tabelle!G92 -> 13651.04
A10: 2024 | B10: 9 | C10: F05 | D10: 27.76 | E10: 35916 | H10: =Tabelle!F119 -> 0.2904 | J10: =Tabelle!B119 -> 52599 | K10: =Tabelle!G93 -> 15277.15
A11: 2024 | B11: 10 | C11: F05 | D11: 135.31 | E11: 182384 | H11: =Tabelle!F120 -> 0.2856 | J11: =Tabelle!B120 -> 54362 | K11: =Tabelle!G94 -> 15523.99
A12: 2024 | B12: 11 | C12: F05 | D12: =Tabelle!F20 -> 86.7 | E12: =Tabelle!F36 -> 80240 | F12: =Tabelle!F4 -> 1109.48 | H12: =Tabelle!F121 -> 0.307 | I12: =F12*H12 -> 340.61036 | J12: =Tabelle!B121 -> 64157 | K12: =Tabelle!G95 -> 19751.41
A13: 2024 | B13: 12 | C13: F05 | D13: =Tabelle!F21 -> 49.9 | E13: =Tabelle!F37 -> 62800 | F13: =Tabelle!F5 -> 727.99 | H13: =Tabelle!F122 -> 0.331 | I13: =F13*H13 -> 240.96469 | J13: =Tabelle!B122 -> 51593 | K13: =Tabelle!G96 -> 17063.94
A14: 2025 | B14: 1 | C14: F05 | D14: =Tabelle!F22 -> 50.2 | E14: =Tabelle!F38 -> 56800 | F14: =Tabelle!F6 -> 966.37 | H14: =Tabelle!F123 -> 0.335 | I14: =F14*H14 -> 323.73395 | J14: =Tabelle!B123 -> 61904 | K14: =Tabelle!G97 -> 20875.39
A15: 2025 | B15: 2 | C15: F05 | D15: =Tabelle!F23 -> 214.2 | E15: =Tabelle!F39 -> 7216 | F15: =Tabelle!F7 -> 768.65 | H15: =Tabelle!F124 -> 0.334 | I15: =F15*H15 -> 256.7291 | J15: =Tabelle!B124 -> 60366 | K15: =Tabelle!G98 -> 20173.7
A16: 2025 | B16: 3 | C16: F05 | D16: =Tabelle!F24 -> 278.1 | E16: =Tabelle!F40 -> 66544 | F16: =Tabelle!F8 -> 1248.24 | H16: =Tabelle!F125 -> 0.286 | I16: =F16*H16 -> 356.99664 | J16: =Tabelle!B125 -> 58209 | K16: =Tabelle!G99 -> 16648.58
A17: 2025 | B17: 4 | C17: F05 | D17: =Tabelle!F25 -> 43 | E17: =Tabelle!F41 -> 44400 | F17: =Tabelle!F9 -> 1022.11 | H17: =Tabelle!F126 -> 0.2655 | I17: =F17*H17 -> 271.3702 | J17: =Tabelle!B126 -> 41269 | K17: =Tabelle!G100 -> 10956.7
A18: 2025 | B18: 5 | C18: F05 | D18: =Tabelle!F26 -> 66 | E18: =Tabelle!F42 -> 45988 | F18: =Tabelle!F10 -> 1035.31 | H18: =Tabelle!F127 -> 0.2575 | I18: =F18*H18 -> 266.59233 | J18: =Tabelle!B127 -> 30809 | K18: =Tabelle!G101 -> 7932.95
A19: 2025 | B19: 6 | C19: F05 | D19: =Tabelle!F27 -> 30.6 | E19: =Tabelle!F43 -> 25456 | F19: =Tabelle!F11 -> 658.19 | H19: =Tabelle!F128 -> 0.355 | I19: =F19*H19 -> 233.65745 | J19: =Tabelle!B128 -> 33644 | K19: =Tabelle!G102 -> 11949.42
A20: 2025 | B20: 7 | C20: F05 | D20: =Tabelle!F28 -> 72.5 | E20: =Tabelle!F44 -> 85935 | F20: =Tabelle!F12 -> 1172.1 | H20: =Tabelle!F129 -> 0.296 | I20: =F20*H20 -> 346.9416 | J20: =Tabelle!B129 -> 51483 | K20: =Tabelle!G103 -> 15262.33
A21: 2025 | B21: 8 | C21: F05 | D21: =Tabelle!F29 -> 20.61 | E21: =Tabelle!F45 -> 18480 | F21: =Tabelle!F13 -> 211.58 | H21: =Tabelle!F130 -> 0.3268 | I21: =F21*H21 -> 69.144344 | J21: =Tabelle!B130 -> 17650 | K21: =Tabelle!G104 -> 5768.63
A22: 2025 | B22: 9 | C22: F05 | D22: =Tabelle!F30 -> 30.81 | E22: =Tabelle!F46 -> 33648 | F22: =Tabelle!F14 -> 1024.98 | H22: =Tabelle!F131 -> 0.2732 | I22: =F22*H22 -> 280.02454 | J22: =Tabelle!B131 -> 47214 | K22: =Tabelle!G105 -> 12897.86
A23: 2025 | B23: 10 | C23: F05 | D23: =Tabelle!F31 -> 0 | E23: =Tabelle!F47 -> 0 | F23: =Tabelle!F15 -> 445.95 | H23: =Tabelle!F132 -> 0.2134 | I23: =F23*H23 -> 95.16573 | J23: =Tabelle!B132 -> 47533 | K23: =Tabelle!G106 -> 13101.09
A24: 2025 | B24: 11 | C24: F05 | H24: =Tabelle!F133 -> 0.2261 | J24: =Tabelle!B133 -> 50662 | K24: =Tabelle!G111 -> 0
A25: 2025 | B25: 12 | C25: F05 | H25: =Tabelle!F134 -> 0 | J25: =Tabelle!B134 -> 0 | K25: =Tabelle!G112 -> 0

Sheet F06
A1: anno | B1: mese | C1: macchina o impianto | D1: ore produzione macchina | E1: pezzi prodotti | F1: consumo | G1: lettura | H1: costo energia | I1: costo macchina | J1: consumo da bolletta | K1: totale bolletta
A2: 2024 | B2: 1 | C2: F06 | D2: 117.3 | E2: 54560 | H2: =Tabelle!F111 -> 0.2557 | J2: =Tabelle!B111 -> 64934 | K2: =Tabelle!G85 -> 16601.39
A3: 2024 | B3: 2 | C3: F06 | D3: 187.55 | E3: 82968 | H3: =Tabelle!F112 -> 0.2378 | J3: =Tabelle!B112 -> 71197 | K3: =Tabelle!G86 -> 16934
A4: 2024 | B4: 3 | C4: F06 | D4: 3.82 | E4: 1872 | H4: =Tabelle!F113 -> 0.2428 | J4: =Tabelle!B113 -> 51152 | K4: =Tabelle!G87 -> 12419.74
A5: 2024 | B5: 4 | C5: F06 | D5: 41.12 | E5: 3948 | H5: =Tabelle!F114 -> 0.2416 | J5: =Tabelle!B114 -> 45316 | K5: =Tabelle!G88 -> 10948.47
A6: 2024 | B6: 5 | C6: F06 | D6: 243.62 | E6: 23364 | H6: =Tabelle!F115 -> 0.2507 | J6: =Tabelle!B115 -> 51330 | K6: =Tabelle!G89 -> 12868.58
A7: 2024 | B7: 6 | C7: F06 | D7: 22.67 | E7: 8150 | H7: =Tabelle!F116 -> 0.2722 | J7: =Tabelle!B116 -> 42151 | K7: =Tabelle!G90 -> 11473.9
A8: 2024 | B8: 7 | C8: F06 | D8: 198.35 | E8: 47590 | H8: =Tabelle!F117 -> 0.287 | J8: =Tabelle!B117 -> 67581 | K8: =Tabelle!G91 -> 19396.73
A9: 2024 | B9: 8 | C9: F06 | D9: 35.06 | E9: 17544 | H9: =Tabelle!F118 -> 0.3047 | J9: =Tabelle!B118 -> 44796 | K9: =Tabelle!G92 -> 13651.04
A10: 2024 | B10: 9 | C10: F06 | D10: 66.39 | E10: 29790 | H10: =Tabelle!F119 -> 0.2904 | J10: =Tabelle!B119 -> 52599 | K10: =Tabelle!G93 -> 15277.15
A11: 2024 | B11: 10 | C11: F06 | D11: 0 | E11: 0 | H11: =Tabelle!F120 -> 0.2856 | J11: =Tabelle!B120 -> 54362 | K11: =Tabelle!G94 -> 15523.99
A12: 2024 | B12: 11 | C12: F06 | D12: =Tabelle!G20 -> 145.9 | E12: =Tabelle!G36 -> 67158 | F12: =Tabelle!G4 -> 1373.24 | H12: =Tabelle!F121 -> 0.307 | I12: =F12*H12 -> 421.58468 | J12: =Tabelle!B121 -> 64157 | K12: =Tabelle!G95 -> 19751.41
A13: 2024 | B13: 12 | C13: F06 | D13: =Tabelle!G21 -> 61 | E13: =Tabelle!G37 -> 26980 | F13: =Tabelle!G5 -> 597.15 | H13: =Tabelle!F122 -> 0.331 | I13: =F13*H13 -> 197.65665 | J13: =Tabelle!B122 -> 51593 | K13: =Tabelle!G96 -> 17063.94
A14: 2025 | B14: 1 | C14: F06 | D14: =Tabelle!G22 -> 96 | E14: =Tabelle!G38 -> 41000 | F14: =Tabelle!G6 -> 824.66 | H14: =Tabelle!F123 -> 0.335 | I14: =F14*H14 -> 276.2611 | J14: =Tabelle!B123 -> 61904 | K14: =Tabelle!G97 -> 20875.39
A15: 2025 | B15: 2 | C15: F06 | D15: =Tabelle!G23 -> 66.9 | E15: =Tabelle!G39 -> 21616 | F15: =Tabelle!G7 -> 747.68 | H15: =Tabelle!F124 -> 0.334 | I15: =F15*H15 -> 249.72512 | J15: =Tabelle!B124 -> 60366 | K15: =Tabelle!G98 -> 20173.7
A16: 2025 | B16: 3 | C16: F06 | D16: =Tabelle!G24 -> 202.5 | E16: =Tabelle!G40 -> 40006 | F16: =Tabelle!G8 -> 1177.48 | H16: =Tabelle!F125 -> 0.286 | I16: =F16*H16 -> 336.75928 | J16: =Tabelle!B125 -> 58209 | K16: =Tabelle!G99 -> 16648.58
A17: 2025 | B17: 4 | C17: F06 | D17: =Tabelle!G25 -> 124.6 | E17: =Tabelle!G41 -> 22826 | F17: =Tabelle!G9 -> 728.78 | H17: =Tabelle!F126 -> 0.2655 | I17: =F17*H17 -> 193.49109 | J17: =Tabelle!B126 -> 41269 | K17: =Tabelle!G100 -> 10956.7
A18: 2025 | B18: 5 | C18: F06 | D18: =Tabelle!G26 -> 116.7 | E18: =Tabelle!G42 -> 44200 | F18: =Tabelle!G10 -> 1032.12 | H18: =Tabelle!F127 -> 0.2575 | I18: =F18*H18 -> 265.7709 | J18: =Tabelle!B127 -> 30809 | K18: =Tabelle!G101 -> 7932.95
A19: 2025 | B19: 6 | C19: F06 | D19: =Tabelle!G27 -> 51.6 | E19: =Tabelle!G43 -> 33550 | F19: =Tabelle!G11 -> 551.61 | H19: =Tabelle!F128 -> 0.355 | I19: =F19*H19 -> 195.82155 | J19: =Tabelle!B128 -> 33644 | K19: =Tabelle!G102 -> 11949.42
A20: 2025 | B20: 7 | C20: F06 | D20: =Tabelle!G28 -> 32.6 | E20: =Tabelle!G44 -> 41334 | F20: =Tabelle!G12 -> 446.96 | H20: =Tabelle!F129 -> 0.296 | I20: =F20*H20 -> 132.30016 | J20: =Tabelle!B129 -> 51483 | K20: =Tabelle!G103 -> 15262.33
A21: 2025 | B21: 8 | C21: F06 | D21: =Tabelle!G29 -> 2.08 | E21: =Tabelle!G45 -> 200 | F21: =Tabelle!G13 -> 113.36 | H21: =Tabelle!F130 -> 0.3268 | I21: =F21*H21 -> 37.046048 | J21: =Tabelle!B130 -> 17650 | K21: =Tabelle!G104 -> 5768.63
A22: 2025 | B22: 9 | C22: F06 | D22: =Tabelle!G30 -> 78.24 | E22: =Tabelle!G46 -> 52692 | F22: =Tabelle!G14 -> 672.85 | H22: =Tabelle!F131 -> 0.2732 | I22: =F22*H22 -> 183.82262 | J22: =Tabelle!B131 -> 47214 | K22: =Tabelle!G105 -> 12897.86
A23: 2025 | B23: 10 | C23: F06 | D23: =Tabelle!G31 -> 60.92 | E23: =Tabelle!G47 -> 29500 | F23: =Tabelle!G15 -> 897.53 | H23: =Tabelle!F132 -> 0.2134 | I23: =F23*H23 -> 191.5329 | J23: =Tabelle!B132 -> 47533 | K23: =Tabelle!G106 -> 13101.09
A24: 2025 | B24: 11 | C24: F06 | H24: =Tabelle!F133 -> 0.2261 | J24: =Tabelle!B133 -> 50662 | K24: =Tabelle!G111 -> 0
A25: 2025 | B25: 12 | C25: F06 | H25: =Tabelle!F134 -> 0 | J25: =Tabelle!B134 -> 0 | K25: =Tabelle!G112 -> 0

Sheet F07
A1: anno | B1: mese | C1: macchina o impianto | D1: ore produzione macchina | E1: pezzi prodotti | F1: consumo | G1: lettura | H1: costo energia | I1: costo macchina | J1: consumo da bolletta | K1: totale bolletta
A2: 2024 | B2: 1 | C2: F07 | D2: 129.86 | E2: 145474 | H2: =Tabelle!F111 -> 0.2557 | J2: =Tabelle!B111 -> 64934 | K2: =Tabelle!G85 -> 16601.39
A3: 2024 | B3: 2 | C3: F07 | D3: 52.81 | E3: 53208 | H3: =Tabelle!F112 -> 0.2378 | J3: =Tabelle!B112 -> 71197 | K3: =Tabelle!G86 -> 16934
A4: 2024 | B4: 3 | C4: F07 | D4: 172.01 | E4: 61792 | H4: =Tabelle!F113 -> 0.2428 | J4: =Tabelle!B113 -> 51152 | K4: =Tabelle!G87 -> 12419.74
A5: 2024 | B5: 4 | C5: F07 | D5: 9.83 | E5: 5000 | H5: =Tabelle!F114 -> 0.2416 | J5: =Tabelle!B114 -> 45316 | K5: =Tabelle!G88 -> 10948.47
A6: 2024 | B6: 5 | C6: F07 | D6: 37.41 | E6: 17596 | H6: =Tabelle!F115 -> 0.2507 | J6: =Tabelle!B115 -> 51330 | K6: =Tabelle!G89 -> 12868.58
A7: 2024 | B7: 6 | C7: F07 | D7: 34.11 | E7: 6200 | H7: =Tabelle!F116 -> 0.2722 | J7: =Tabelle!B116 -> 42151 | K7: =Tabelle!G90 -> 11473.9
A8: 2024 | B8: 7 | C8: F07 | D8: 20.08 | E8: 9210 | H8: =Tabelle!F117 -> 0.287 | J8: =Tabelle!B117 -> 67581 | K8: =Tabelle!G91 -> 19396.73
A9: 2024 | B9: 8 | C9: F07 | D9: 84.86 | E9: 38850 | H9: =Tabelle!F118 -> 0.3047 | J9: =Tabelle!B118 -> 44796 | K9: =Tabelle!G92 -> 13651.04
A10: 2024 | B10: 9 | C10: F07 | D10: 52.05 | E10: 22439 | H10: =Tabelle!F119 -> 0.2904 | J10: =Tabelle!B119 -> 52599 | K10: =Tabelle!G93 -> 15277.15
A11: 2024 | B11: 10 | C11: F07 | D11: 51.1 | E11: 22392 | H11: =Tabelle!F120 -> 0.2856 | J11: =Tabelle!B120 -> 54362 | K11: =Tabelle!G94 -> 15523.99
A12: 2024 | B12: 11 | C12: F07 | D12: =Tabelle!H20 -> 175.2 | E12: =Tabelle!H36 -> 86620 | F12: =Tabelle!H4 -> 1496.8 | H12: =Tabelle!F121 -> 0.307 | I12: =F12*H12 -> 459.5176 | J12: =Tabelle!B121 -> 64157 | K12: =Tabelle!G95 -> 19751.41
A13: 2024 | B13: 12 | C13: F07 | D13: =Tabelle!H21 -> 103.7 | E13: =Tabelle!H37 -> 60888 | F13: =Tabelle!H5 -> 1222.84 | H13: =Tabelle!F122 -> 0.331 | I13: =F13*H13 -> 404.76004 | J13: =Tabelle!B122 -> 51593 | K13: =Tabelle!G96 -> 17063.94
A14: 2025 | B14: 1 | C14: F07 | D14: =Tabelle!H22 -> 130.7 | E14: =Tabelle!H38 -> 35268 | F14: =Tabelle!H6 -> 828.56 | H14: =Tabelle!F123 -> 0.335 | I14: =F14*H14 -> 277.5676 | J14: =Tabelle!B123 -> 61904 | K14: =Tabelle!G97 -> 20875.39
A15: 2025 | B15: 2 | C15: F07 | D15: =Tabelle!H23 -> 39.5 | E15: =Tabelle!H39 -> 10207 | F15: =Tabelle!H7 -> 644.72 | H15: =Tabelle!F124 -> 0.334 | I15: =F15*H15 -> 215.33648 | J15: =Tabelle!B124 -> 60366 | K15: =Tabelle!G98 -> 20173.7
A16: 2025 | B16: 3 | C16: F07 | D16: =Tabelle!H24 -> 74.3 | E16: =Tabelle!H40 -> 36000 | F16: =Tabelle!H8 -> 1169.04 | H16: =Tabelle!F125 -> 0.286 | I16: =F16*H16 -> 334.34544 | J16: =Tabelle!B125 -> 58209 | K16: =Tabelle!G99 -> 16648.58
A17: 2025 | B17: 4 | C17: F07 | D17: =Tabelle!H25 -> 47.6 | E17: =Tabelle!H41 -> 26552 | F17: =Tabelle!H9 -> 911.76 | H17: =Tabelle!F126 -> 0.2655 | I17: =F17*H17 -> 242.07228 | J17: =Tabelle!B126 -> 41269 | K17: =Tabelle!G100 -> 10956.7
A18: 2025 | B18: 5 | C18: F07 | D18: =Tabelle!H26 -> 0 | E18: =Tabelle!H42 -> 0 | F18: =Tabelle!H10 -> 341.74 | H18: =Tabelle!F127 -> 0.2575 | I18: =F18*H18 -> 87.99805 | J18: =Tabelle!B127 -> 30809 | K18: =Tabelle!G101 -> 7932.95
A19: 2025 | B19: 6 | C19: F07 | D19: =Tabelle!H27 -> 47.1 | E19: =Tabelle!H43 -> 14836 | F19: =Tabelle!H11 -> 711.03 | H19: =Tabelle!F128 -> 0.355 | I19: =F19*H19 -> 252.41565 | J19: =Tabelle!B128 -> 33644 | K19: =Tabelle!G102 -> 11949.42
A20: 2025 | B20: 7 | C20: F07 | D20: =Tabelle!H28 -> 56.1 | E20: =Tabelle!H44 -> 46226 | F20: =Tabelle!H12 -> 601.34 | H20: =Tabelle!F129 -> 0.296 | I20: =F20*H20 -> 177.99664 | J20: =Tabelle!B129 -> 51483 | K20: =Tabelle!G103 -> 15262.33
A21: 2025 | B21: 8 | C21: F07 | D21: =Tabelle!H29 -> 53.68 | E21: =Tabelle!H45 -> 51700 | F21: =Tabelle!H13 -> 238.85 | H21: =Tabelle!F130 -> 0.3268 | I21: =F21*H21 -> 78.05618 | J21: =Tabelle!B130 -> 17650 | K21: =Tabelle!G104 -> 5768.63
A22: 2025 | B22: 9 | C22: F07 | D22: =Tabelle!H30 -> 220.84 | E22: =Tabelle!H46 -> 174681 | F22: =Tabelle!H14 -> 1110.88 | H22: =Tabelle!F131 -> 0.2732 | I22: =F22*H22 -> 303.49242 | J22: =Tabelle!B131 -> 47214 | K22: =Tabelle!G105 -> 12897.86
A23: 2025 | B23: 10 | C23: F07 | D23: =Tabelle!H31 -> 26.5 | E23: =Tabelle!H47 -> 27000 | F23: =Tabelle!H15 -> 959.77 | H23: =Tabelle!F132 -> 0.2134 | I23: =F23*H23 -> 204.81492 | J23: =Tabelle!B132 -> 47533 | K23: =Tabelle!G106 -> 13101.09
A24: 2025 | B24: 11 | C24: F07 | H24: =Tabelle!F133 -> 0.2261 | J24: =Tabelle!B133 -> 50662 | K24: =Tabelle!G111 -> 0
A25: 2025 | B25: 12 | C25: F07 | H25: =Tabelle!F134 -> 0 | J25: =Tabelle!B134 -> 0 | K25: =Tabelle!G112 -> 0

Sheet F08
A1: anno | B1: mese | C1: macchina o impianto | D1: ore produzione macchina | E1: pezzi prodotti | F1: consumo | G1: lettura | H1: costo energia | I1: costo macchina | J1: consumo da bolletta | K1: totale bolletta
A2: 2024 | B2: 1 | C2: F08 | D2: 93.13 | E2: 56800 | H2: =Tabelle!F111 -> 0.2557 | J2: =Tabelle!B111 -> 64934 | K2: =Tabelle!G85 -> 16601.39
A3: 2024 | B3: 2 | C3: F08 | D3: 46.78 | E3: 47188 | H3: =Tabelle!F112 -> 0.2378 | J3: =Tabelle!B112 -> 71197 | K3: =Tabelle!G86 -> 16934
A4: 2024 | B4: 3 | C4: F08 | D4: 70.5 | E4: 13740 | H4: =Tabelle!F113 -> 0.2428 | J4: =Tabelle!B113 -> 51152 | K4: =Tabelle!G87 -> 12419.74
A5: 2024 | B5: 4 | C5: F08 | D5: 12.87 | E5: 2766 | H5: =Tabelle!F114 -> 0.2416 | J5: =Tabelle!B114 -> 45316 | K5: =Tabelle!G88 -> 10948.47
A6: 2024 | B6: 5 | C6: F08 | D6: 0.11 | E6: 24 | H6: =Tabelle!F115 -> 0.2507 | J6: =Tabelle!B115 -> 51330 | K6: =Tabelle!G89 -> 12868.58
A7: 2024 | B7: 6 | C7: F08 | D7: 0.43 | E7: 248 | H7: =Tabelle!F116 -> 0.2722 | J7: =Tabelle!B116 -> 42151 | K7: =Tabelle!G90 -> 11473.9
A8: 2024 | B8: 7 | C8: F08 | D8: 29.16 | E8: 25648 | H8: =Tabelle!F117 -> 0.287 | J8: =Tabelle!B117 -> 67581 | K8: =Tabelle!G91 -> 19396.73
A9: 2024 | B9: 8 | C9: F08 | D9: 32.63 | E9: 8515 | H9: =Tabelle!F118 -> 0.3047 | J9: =Tabelle!B118 -> 44796 | K9: =Tabelle!G92 -> 13651.04
A10: 2024 | B10: 9 | C10: F08 | D10: 53.67 | E10: 26900 | H10: =Tabelle!F119 -> 0.2904 | J10: =Tabelle!B119 -> 52599 | K10: =Tabelle!G93 -> 15277.15
A11: 2024 | B11: 10 | C11: F08 | D11: 35.61 | E11: 14098 | H11: =Tabelle!F120 -> 0.2856 | J11: =Tabelle!B120 -> 54362 | K11: =Tabelle!G94 -> 15523.99
A12: 2024 | B12: 11 | C12: F08 | D12: =Tabelle!I20 -> 121.9 | E12: =Tabelle!I36 -> 31407 | F12: =Tabelle!I4 -> 835.77 | H12: =Tabelle!F121 -> 0.307 | I12: =F12*H12 -> 256.58139 | J12: =Tabelle!B121 -> 64157 | K12: =Tabelle!G95 -> 19751.41
A13: 2024 | B13: 12 | C13: F08 | D13: =Tabelle!I21 -> 72 | E13: =Tabelle!I37 -> 48221 | F13: =Tabelle!I5 -> 578.67 | H13: =Tabelle!F122 -> 0.331 | I13: =F13*H13 -> 191.53977 | J13: =Tabelle!B122 -> 51593 | K13: =Tabelle!G96 -> 17063.94
A14: 2025 | B14: 1 | C14: F08 | D14: =Tabelle!I22 -> 147.6 | E14: =Tabelle!I38 -> 67400 | F14: =Tabelle!I6 -> 910.71 | H14: =Tabelle!F123 -> 0.335 | I14: =F14*H14 -> 305.08785 | J14: =Tabelle!B123 -> 61904 | K14: =Tabelle!G97 -> 20875.39
A15: 2025 | B15: 2 | C15: F08 | D15: =Tabelle!I23 -> 37.1 | E15: =Tabelle!I39 -> 23510 | F15: =Tabelle!I7 -> 770.35 | H15: =Tabelle!F124 -> 0.334 | I15: =F15*H15 -> 257.2969 | J15: =Tabelle!B124 -> 60366 | K15: =Tabelle!G98 -> 20173.7
A16: 2025 | B16: 3 | C16: F08 | D16: =Tabelle!I24 -> 77.5 | E16: =Tabelle!I40 -> 11300 | F16: =Tabelle!I8 -> 1060.23 | H16: =Tabelle!F125 -> 0.286 | I16: =F16*H16 -> 303.22578 | J16: =Tabelle!B125 -> 58209 | K16: =Tabelle!G99 -> 16648.58
A17: 2025 | B17: 4 | C17: F08 | D17: =Tabelle!I25 -> 70.6 | E17: =Tabelle!I41 -> 15552 | F17: =Tabelle!I9 -> 824.31 | H17: =Tabelle!F126 -> 0.2655 | I17: =F17*H17 -> 218.85431 | J17: =Tabelle!B126 -> 41269 | K17: =Tabelle!G100 -> 10956.7
A18: 2025 | B18: 5 | C18: F08 | D18: =Tabelle!I26 -> 58.7 | E18: =Tabelle!I42 -> 11985 | F18: =Tabelle!I10 -> 586.48 | H18: =Tabelle!F127 -> 0.2575 | I18: =F18*H18 -> 151.0186 | J18: =Tabelle!B127 -> 30809 | K18: =Tabelle!G101 -> 7932.95
A19: 2025 | B19: 6 | C19: F08 | D19: =Tabelle!I27 -> 83.5 | E19: =Tabelle!I43 -> 14828 | F19: =Tabelle!I11 -> 840.06 | H19: =Tabelle!F128 -> 0.355 | I19: =F19*H19 -> 298.2213 | J19: =Tabelle!B128 -> 33644 | K19: =Tabelle!G102 -> 11949.42
A20: 2025 | B20: 7 | C20: F08 | D20: =Tabelle!I28 -> 131.1 | E20: =Tabelle!I44 -> 115922 | F20: =Tabelle!I12 -> 1044.72 | H20: =Tabelle!F129 -> 0.296 | I20: =F20*H20 -> 309.23712 | J20: =Tabelle!B129 -> 51483 | K20: =Tabelle!G103 -> 15262.33
A21: 2025 | B21: 8 | C21: F08 | D21: =Tabelle!I29 -> 0 | E21: =Tabelle!I45 -> 0 | F21: =Tabelle!I13 -> 7.18 | H21: =Tabelle!F130 -> 0.3268 | I21: =F21*H21 -> 2.346424 | J21: =Tabelle!B130 -> 17650 | K21: =Tabelle!G104 -> 5768.63
A22: 2025 | B22: 9 | C22: F08 | D22: =Tabelle!I30 -> 0 | E22: =Tabelle!I46 -> 0 | F22: =Tabelle!I14 -> 0 | H22: =Tabelle!F131 -> 0.2732 | I22: =F22*H22 -> 0 | J22: =Tabelle!B131 -> 47214 | K22: =Tabelle!G105 -> 12897.86
A23: 2025 | B23: 10 | C23: F08 | D23: =Tabelle!I31 -> 0 | E23: =Tabelle!I47 -> 0 | F23: =Tabelle!I15 -> 0 | H23: =Tabelle!F132 -> 0.2134 | I23: =F23*H23 -> 0 | J23: =Tabelle!B132 -> 47533 | K23: =Tabelle!G106 -> 13101.09
A24: 2025 | B24: 11 | C24: F08 | H24: =Tabelle!F133 -> 0.2261 | J24: =Tabelle!B133 -> 50662 | K24: =Tabelle!G111 -> 0
A25: 2025 | B25: 12 | C25: F08 | H25: =Tabelle!F134 -> 0 | J25: =Tabelle!B134 -> 0 | K25: =Tabelle!G112 -> 0

Sheet F09
A1: anno | B1: mese | C1: macchina o impianto | D1: ore produzione macchina | E1: pezzi prodotti | F1: consumo | G1: lettura | H1: costo energia | I1: costo macchina | J1: consumo da bolletta | K1: totale bolletta
A2: 2024 | B2: 1 | C2: F09 | D2: 129.43 | E2: 45447 | H2: =Tabelle!F111 -> 0.2557 | J2: =Tabelle!B111 -> 64934 | K2: =Tabelle!G85 -> 16601.39
A3: 2024 | B3: 2 | C3: F09 | D3: 108.66 | E3: 27652 | H3: =Tabelle!F112 -> 0.2378 | J3: =Tabelle!B112 -> 71197 | K3: =Tabelle!G86 -> 16934
A4: 2024 | B4: 3 | C4: F09 | D4: 111.16 | E4: 36608 | H4: =Tabelle!F113 -> 0.2428 | J4: =Tabelle!B113 -> 51152 | K4: =Tabelle!G87 -> 12419.74
A5: 2024 | B5: 4 | C5: F09 | D5: 43.4 | E5: 15452 | H5: =Tabelle!F114 -> 0.2416 | J5: =Tabelle!B114 -> 45316 | K5: =Tabelle!G88 -> 10948.47
A6: 2024 | B6: 5 | C6: F09 | D6: 65.24 | E6: 17425 | H6: =Tabelle!F115 -> 0.2507 | J6: =Tabelle!B115 -> 51330 | K6: =Tabelle!G89 -> 12868.58
A7: 2024 | B7: 6 | C7: F09 | D7: 0 | E7: 0 | H7: =Tabelle!F116 -> 0.2722 | J7: =Tabelle!B116 -> 42151 | K7: =Tabelle!G90 -> 11473.9
A8: 2024 | B8: 7 | C8: F09 | D8: 53.62 | E8: 5264 | H8: =Tabelle!F117 -> 0.287 | J8: =Tabelle!B117 -> 67581 | K8: =Tabelle!G91 -> 19396.73
A9: 2024 | B9: 8 | C9: F09 | D9: 14.37 | E9: 2128 | H9: =Tabelle!F118 -> 0.3047 | J9: =Tabelle!B118 -> 44796 | K9: =Tabelle!G92 -> 13651.04
A10: 2024 | B10: 9 | C10: F09 | D10: 24.86 | E10: 15040 | H10: =Tabelle!F119 -> 0.2904 | J10: =Tabelle!B119 -> 52599 | K10: =Tabelle!G93 -> 15277.15
A11: 2024 | B11: 10 | C11: F09 | D11: 22.06 | E11: 9360 | H11: =Tabelle!F120 -> 0.2856 | J11: =Tabelle!B120 -> 54362 | K11: =Tabelle!G94 -> 15523.99
A12: 2024 | B12: 11 | C12: F09 | D12: =Tabelle!J20 -> 50.7 | E12: =Tabelle!J36 -> 23463 | F12: =Tabelle!J4 -> 449.71 | H12: =Tabelle!F121 -> 0.307 | I12: =F12*H12 -> 138.06097 | J12: =Tabelle!B121 -> 64157 | K12: =Tabelle!G95 -> 19751.41
A13: 2024 | B13: 12 | C13: F09 | D13: =Tabelle!J21 -> 12.4 | E13: =Tabelle!J37 -> 3993 | F13: =Tabelle!J5 -> 164.26 | H13: =Tabelle!F122 -> 0.331 | I13: =F13*H13 -> 54.37006 | J13: =Tabelle!B122 -> 51593 | K13: =Tabelle!G96 -> 17063.94
A14: 2025 | B14: 1 | C14: F09 | D14: =Tabelle!J22 -> 2.3 | E14: =Tabelle!J38 -> 9 | F14: =Tabelle!J6 -> 135.3 | H14: =Tabelle!F123 -> 0.335 | I14: =F14*H14 -> 45.3255 | J14: =Tabelle!B123 -> 61904 | K14: =Tabelle!G97 -> 20875.39
A15: 2025 | B15: 2 | C15: F09 | D15: =Tabelle!J23 -> 64.1 | E15: =Tabelle!J39 -> 36009 | F15: =Tabelle!J7 -> 341.64 | H15: =Tabelle!F124 -> 0.334 | I15: =F15*H15 -> 114.10776 | J15: =Tabelle!B124 -> 60366 | K15: =Tabelle!G98 -> 20173.7
A16: 2025 | B16: 3 | C16: F09 | D16: =Tabelle!J24 -> 99.4 | E16: =Tabelle!J40 -> 22178 | F16: =Tabelle!J8 -> 401.27 | H16: =Tabelle!F125 -> 0.286 | I16: =F16*H16 -> 114.76322 | J16: =Tabelle!B125 -> 58209 | K16: =Tabelle!G99 -> 16648.58
A17: 2025 | B17: 4 | C17: F09 | D17: =Tabelle!J25 -> 66 | E17: =Tabelle!J41 -> 16806 | F17: =Tabelle!J9 -> 375.39 | H17: =Tabelle!F126 -> 0.2655 | I17: =F17*H17 -> 99.666045 | J17: =Tabelle!B126 -> 41269 | K17: =Tabelle!G100 -> 10956.7
A18: 2025 | B18: 5 | C18: F09 | D18: =Tabelle!J26 -> 0 | E18: =Tabelle!J42 -> 0 | F18: =Tabelle!J10 -> 23.6 | H18: =Tabelle!F127 -> 0.2575 | I18: =F18*H18 -> 6.077 | J18: =Tabelle!B127 -> 30809 | K18: =Tabelle!G101 -> 7932.95
A19: 2025 | B19: 6 | C19: F09 | D19: =Tabelle!J27 -> 19.5 | E19: =Tabelle!J43 -> 13125 | F19: =Tabelle!J11 -> 159.25 | H19: =Tabelle!F128 -> 0.355 | I19: =F19*H19 -> 56.53375 | J19: =Tabelle!B128 -> 33644 | K19: =Tabelle!G102 -> 11949.42
A20: 2025 | B20: 7 | C20: F09 | D20: =Tabelle!J28 -> 57.8 | E20: =Tabelle!J44 -> 18000 | F20: =Tabelle!J12 -> 262.42 | H20: =Tabelle!F129 -> 0.296 | I20: =F20*H20 -> 77.67632 | J20: =Tabelle!B129 -> 51483 | K20: =Tabelle!G103 -> 15262.33
A21: 2025 | B21: 8 | C21: F09 | D21: =Tabelle!J29 -> 8.56 | E21: =Tabelle!J45 -> 5000 | F21: =Tabelle!J13 -> 76.19 | H21: =Tabelle!F130 -> 0.3268 | I21: =F21*H21 -> 24.898892 | J21: =Tabelle!B130 -> 17650 | K21: =Tabelle!G104 -> 5768.63
A22: 2025 | B22: 9 | C22: F09 | D22: =Tabelle!J30 -> 25.67 | E22: =Tabelle!J46 -> 18360 | F22: =Tabelle!J14 -> 293.54 | H22: =Tabelle!F131 -> 0.2732 | I22: =F22*H22 -> 80.195128 | J22: =Tabelle!B131 -> 47214 | K22: =Tabelle!G105 -> 12897.86
A23: 2025 | B23: 10 | C23: F09 | D23: =Tabelle!J31 -> 0 | E23: =Tabelle!J47 -> 0 | F23: =Tabelle!J15 -> 39.77 | H23: =Tabelle!F132 -> 0.2134 | I23: =F23*H23 -> 8.486918 | J23: =Tabelle!B132 -> 47533 | K23: =Tabelle!G106 -> 13101.09
A24: 2025 | B24: 11 | C24: F09 | H24: =Tabelle!F133 -> 0.2261 | J24: =Tabelle!B133 -> 50662 | K24: =Tabelle!G111 -> 0
A25: 2025 | B25: 12 | C25: F09 | H25: =Tabelle!F134 -> 0 | J25: =Tabelle!B134 -> 0 | K25: =Tabelle!G112 -> 0

Sheet F10
A1: anno | B1: mese | C1: macchina o impianto | D1: ore produzione macchina | E1: pezzi prodotti | F1: consumo | G1: lettura | H1: costo energia | I1: costo macchina | J1: consumo da bolletta | K1: totale bolletta
A2: 2024 | B2: 1 | C2: F10 | D2: 101.86 | E2: 38280 | H2: =Tabelle!F111 -> 0.2557 | J2: =Tabelle!B111 -> 64934 | K2: =Tabelle!G85 -> 16601.39
A3: 2024 | B3: 2 | C3: F10 | D3: 209.38 | E3: 52900 | H3: =Tabelle!F112 -> 0.2378 | J3: =Tabelle!B112 -> 71197 | K3: =Tabelle!G86 -> 16934
A4: 2024 | B4: 3 | C4: F10 | D4: 38.6 | E4: 47680 | H4: =Tabelle!F113 -> 0.2428 | J4: =Tabelle!B113 -> 51152 | K4: =Tabelle!G87 -> 12419.74
A5: 2024 | B5: 4 | C5: F10 | D5: 253.99 | E5: 21709 | H5: =Tabelle!F114 -> 0.2416 | J5: =Tabelle!B114 -> 45316 | K5: =Tabelle!G88 -> 10948.47
A6: 2024 | B6: 5 | C6: F10 | D6: 160.65 | E6: 29355 | H6: =Tabelle!F115 -> 0.2507 | J6: =Tabelle!B115 -> 51330 | K6: =Tabelle!G89 -> 12868.58
A7: 2024 | B7: 6 | C7: F10 | D7: 36.54 | E7: 20502 | H7: =Tabelle!F116 -> 0.2722 | J7: =Tabelle!B116 -> 42151 | K7: =Tabelle!G90 -> 11473.9
A8: 2024 | B8: 7 | C8: F10 | D8: 0 | E8: 0 | H8: =Tabelle!F117 -> 0.287 | J8: =Tabelle!B117 -> 67581 | K8: =Tabelle!G91 -> 19396.73
A9: 2024 | B9: 8 | C9: F10 | D9: 23.03 | E9: 10980 | H9: =Tabelle!F118 -> 0.3047 | J9: =Tabelle!B118 -> 44796 | K9: =Tabelle!G92 -> 13651.04
A10: 2024 | B10: 9 | C10: F10 | D10: 51.57 | E10: 26298 | H10: =Tabelle!F119 -> 0.2904 | J10: =Tabelle!B119 -> 52599 | K10: =Tabelle!G93 -> 15277.15
A11: 2024 | B11: 10 | C11: F10 | D11: 21.41 | E11: 4628 | H11: =Tabelle!F120 -> 0.2856 | J11: =Tabelle!B120 -> 54362 | K11: =Tabelle!G94 -> 15523.99
A12: 2024 | B12: 11 | C12: F10 | D12: =Tabelle!K20 -> 55.1 | E12: =Tabelle!K36 -> 31023 | F12: =Tabelle!K4 -> 889.11 | H12: =Tabelle!F121 -> 0.307 | I12: =F12*H12 -> 272.95677 | J12: =Tabelle!B121 -> 64157 | K12: =Tabelle!G95 -> 19751.41
A13: 2024 | B13: 12 | C13: F10 | D13: =Tabelle!K21 -> 2.1 | E13: =Tabelle!K37 -> 2616 | F13: =Tabelle!K5 -> 289.65 | H13: =Tabelle!F122 -> 0.331 | I13: =F13*H13 -> 95.87415 | J13: =Tabelle!B122 -> 51593 | K13: =Tabelle!G96 -> 17063.94
A14: 2025 | B14: 1 | C14: F10 | D14: =Tabelle!K22 -> 31.5 | E14: =Tabelle!K38 -> 8619 | F14: =Tabelle!K6 -> 580.88 | H14: =Tabelle!F123 -> 0.335 | I14: =F14*H14 -> 194.5948 | J14: =Tabelle!B123 -> 61904 | K14: =Tabelle!G97 -> 20875.39
A15: 2025 | B15: 2 | C15: F10 | D15: =Tabelle!K23 -> 92.6 | E15: =Tabelle!K39 -> 29278 | F15: =Tabelle!K7 -> 920.21 | H15: =Tabelle!F124 -> 0.334 | I15: =F15*H15 -> 307.35014 | J15: =Tabelle!B124 -> 60366 | K15: =Tabelle!G98 -> 20173.7
A16: 2025 | B16: 3 | C16: F10 | D16: =Tabelle!K24 -> 79.9 | E16: =Tabelle!K40 -> 33501 | F16: =Tabelle!K8 -> 1017.88 | H16: =Tabelle!F125 -> 0.286 | I16: =F16*H16 -> 291.11368 | J16: =Tabelle!B125 -> 58209 | K16: =Tabelle!G99 -> 16648.58
A17: 2025 | B17: 4 | C17: F10 | D17: =Tabelle!K25 -> 164.8 | E17: =Tabelle!K41 -> 70944 | F17: =Tabelle!K9 -> 1182.44 | H17: =Tabelle!F126 -> 0.2655 | I17: =F17*H17 -> 313.93782 | J17: =Tabelle!B126 -> 41269 | K17: =Tabelle!G100 -> 10956.7
A18: 2025 | B18: 5 | C18: F10 | D18: =Tabelle!K26 -> 52.2 | E18: =Tabelle!K42 -> 29403 | F18: =Tabelle!K10 -> 610.53 | H18: =Tabelle!F127 -> 0.2575 | I18: =F18*H18 -> 157.21148 | J18: =Tabelle!B127 -> 30809 | K18: =Tabelle!G101 -> 7932.95
A19: 2025 | B19: 6 | C19: F10 | D19: =Tabelle!K27 -> 6.5 | E19: =Tabelle!K43 -> 4800 | F19: =Tabelle!K11 -> 132.48 | H19: =Tabelle!F128 -> 0.355 | I19: =F19*H19 -> 47.0304 | J19: =Tabelle!B128 -> 33644 | K19: =Tabelle!G102 -> 11949.42
A20: 2025 | B20: 7 | C20: F10 | D20: =Tabelle!K28 -> 150.1 | E20: =Tabelle!K44 -> 33092 | F20: =Tabelle!K12 -> 905.03 | H20: =Tabelle!F129 -> 0.296 | I20: =F20*H20 -> 267.88888 | J20: =Tabelle!B129 -> 51483 | K20: =Tabelle!G103 -> 15262.33
A21: 2025 | B21: 8 | C21: F10 | D21: =Tabelle!K29 -> 0 | E21: =Tabelle!K45 -> 0 | F21: =Tabelle!K13 -> 8.82 | H21: =Tabelle!F130 -> 0.3268 | J21: =Tabelle!B130 -> 17650 | K21: =Tabelle!G104 -> 5768.63
A22: 2025 | B22: 9 | C22: F10 | D22: =Tabelle!K30 -> 110.88 | E22: =Tabelle!K46 -> 11782 | F22: =Tabelle!K14 -> 553.54 | H22: =Tabelle!F131 -> 0.2732 | J22: =Tabelle!B131 -> 47214 | K22: =Tabelle!G105 -> 12897.86
A23: 2025 | B23: 10 | C23: F10 | D23: =Tabelle!K31 -> 0 | E23: =Tabelle!K47 -> 0 | F23: =Tabelle!K15 -> 722.6 | H23: =Tabelle!F132 -> 0.2134 | J23: =Tabelle!B132 -> 47533 | K23: =Tabelle!G106 -> 13101.09
A24: 2025 | B24: 11 | C24: F10 | H24: =Tabelle!F133 -> 0.2261 | J24: =Tabelle!B133 -> 50662 | K24: =Tabelle!G111 -> 0
A25: 2025 | B25: 12 | C25: F10 | H25: =Tabelle!F134 -> 0 | J25: =Tabelle!B134 -> 0 | K25: =Tabelle!G112 -> 0

Sheet F11
A1: anno | B1: mese | C1: macchina o impianto | D1: ore produzione macchina | E1: pezzi prodotti | F1: consumo | G1: lettura | H1: costo energia | I1: costo macchina | J1: consumo da bolletta | K1: totale bolletta
A2: 2024 | B2: 1 | C2: F11 | D2: 324.79 | E2: 140670 | H2: =Tabelle!F111 -> 0.2557 | J2: =Tabelle!B111 -> 64934 | K2: =Tabelle!G85 -> 16601.39
A3: 2024 | B3: 2 | C3: F11 | D3: 80.13 | E3: 39140 | H3: =Tabelle!F112 -> 0.2378 | J3: =Tabelle!B112 -> 71197 | K3: =Tabelle!G86 -> 16934
A4: 2024 | B4: 3 | C4: F11 | D4: 16.14 | E4: 8600 | H4: =Tabelle!F113 -> 0.2428 | J4: =Tabelle!B113 -> 51152 | K4: =Tabelle!G87 -> 12419.74
A5: 2024 | B5: 4 | C5: F11 | D5: 18.04 | E5: 10000 | H5: =Tabelle!F114 -> 0.2416 | J5: =Tabelle!B114 -> 45316 | K5: =Tabelle!G88 -> 10948.47
A6: 2024 | B6: 5 | C6: F11 | D6: 113.6 | E6: 68201 | H6: =Tabelle!F115 -> 0.2507 | J6: =Tabelle!B115 -> 51330 | K6: =Tabelle!G89 -> 12868.58
A7: 2024 | B7: 6 | C7: F11 | D7: 89.83 | E7: 45462 | H7: =Tabelle!F116 -> 0.2722 | J7: =Tabelle!B116 -> 42151 | K7: =Tabelle!G90 -> 11473.9
A8: 2024 | B8: 7 | C8: F11 | D8: 320.98 | E8: 135608 | H8: =Tabelle!F117 -> 0.287 | J8: =Tabelle!B117 -> 67581 | K8: =Tabelle!G91 -> 19396.73
A9: 2024 | B9: 8 | C9: F11 | D9: 138.87 | E9: 49569 | H9: =Tabelle!F118 -> 0.3047 | J9: =Tabelle!B118 -> 44796 | K9: =Tabelle!G92 -> 13651.04
A10: 2024 | B10: 9 | C10: F11 | D10: 161.96 | E10: 58891 | H10: =Tabelle!F119 -> 0.2904 | J10: =Tabelle!B119 -> 52599 | K10: =Tabelle!G93 -> 15277.15
A11: 2024 | B11: 10 | C11: F11 | D11: 324.95 | E11: 97270 | H11: =Tabelle!F120 -> 0.2856 | J11: =Tabelle!B120 -> 54362 | K11: =Tabelle!G94 -> 15523.99
A12: 2024 | B12: 11 | C12: F11 | D12: =Tabelle!L20 -> 300.7 | E12: =Tabelle!L36 -> 119234 | F12: =Tabelle!L4 -> 686.86 | H12: =Tabelle!F121 -> 0.307 | I12: =F12*H12 -> 210.86602 | J12: =Tabelle!B121 -> 64157 | K12: =Tabelle!G95 -> 19751.41
A13: 2024 | B13: 12 | C13: F11 | D13: =Tabelle!L21 -> 120.3 | E13: =Tabelle!L37 -> 36466 | F13: =Tabelle!L5 -> 380.23 | H13: =Tabelle!F122 -> 0.331 | I13: =F13*H13 -> 125.85613 | J13: =Tabelle!B122 -> 51593 | K13: =Tabelle!G96 -> 17063.94
A14: 2025 | B14: 1 | C14: F11 | D14: =Tabelle!L22 -> 209.8 | E14: =Tabelle!L38 -> 62417 | F14: =Tabelle!L6 -> 485.73 | H14: =Tabelle!F123 -> 0.335 | I14: =F14*H14 -> 162.71955 | J14: =Tabelle!B123 -> 61904 | K14: =Tabelle!G97 -> 20875.39
A15: 2025 | B15: 2 | C15: F11 | D15: =Tabelle!L23 -> 277 | E15: =Tabelle!L39 -> 96598 | F15: =Tabelle!L7 -> 627.37 | H15: =Tabelle!F124 -> 0.334 | I15: =F15*H15 -> 209.54158 | J15: =Tabelle!B124 -> 60366 | K15: =Tabelle!G98 -> 20173.7
A16: 2025 | B16: 3 | C16: F11 | D16: =Tabelle!L24 -> 259.4 | E16: =Tabelle!L40 -> 83238 | F16: =Tabelle!L8 -> 650.34 | H16: =Tabelle!F125 -> 0.286 | I16: =F16*H16 -> 185.99724 | J16: =Tabelle!B125 -> 58209 | K16: =Tabelle!G99 -> 16648.58
A17: 2025 | B17: 4 | C17: F11 | D17: =Tabelle!L25 -> 243.6 | E17: =Tabelle!L41 -> 86947 | F17: =Tabelle!L9 -> 598.43 | H17: =Tabelle!F126 -> 0.2655 | I17: =F17*H17 -> 158.88316 | J17: =Tabelle!B126 -> 41269 | K17: =Tabelle!G100 -> 10956.7
A18: 2025 | B18: 5 | C18: F11 | D18: =Tabelle!L26 -> 244.8 | E18: =Tabelle!L42 -> 72060 | F18: =Tabelle!L10 -> 484.79 | H18: =Tabelle!F127 -> 0.2575 | I18: =F18*H18 -> 124.83343 | J18: =Tabelle!B127 -> 30809 | K18: =Tabelle!G101 -> 7932.95
A19: 2025 | B19: 6 | C19: F11 | D19: =Tabelle!L27 -> 239.3 | E19: =Tabelle!L43 -> 83892 | F19: =Tabelle!L11 -> 550.08 | H19: =Tabelle!F128 -> 0.355 | I19: =F19*H19 -> 195.2784 | J19: =Tabelle!B128 -> 33644 | K19: =Tabelle!G102 -> 11949.42
A20: 2025 | B20: 7 | C20: F11 | D20: =Tabelle!L28 -> 335.9 | E20: =Tabelle!L44 -> 114871 | F20: =Tabelle!L12 -> 770.29 | H20: =Tabelle!F129 -> 0.296 | I20: =F20*H20 -> 228.00584 | J20: =Tabelle!B129 -> 51483 | K20: =Tabelle!G103 -> 15262.33
